[2023-05-28 00:15:22,152] {taskinstance.py:896} INFO - Dependencies all met for <TaskInstance: stock_market_pipeline_fe.download_dataset 2023-05-28T00:04:05.743782+00:00 [queued]>
[2023-05-28 00:15:22,164] {taskinstance.py:896} INFO - Dependencies all met for <TaskInstance: stock_market_pipeline_fe.download_dataset 2023-05-28T00:04:05.743782+00:00 [queued]>
[2023-05-28 00:15:22,164] {taskinstance.py:1087} INFO - 
--------------------------------------------------------------------------------
[2023-05-28 00:15:22,164] {taskinstance.py:1088} INFO - Starting attempt 2 of 4
[2023-05-28 00:15:22,165] {taskinstance.py:1089} INFO - 
--------------------------------------------------------------------------------
[2023-05-28 00:15:22,172] {taskinstance.py:1107} INFO - Executing <Task(PythonOperator): download_dataset> on 2023-05-28T00:04:05.743782+00:00
[2023-05-28 00:15:22,175] {standard_task_runner.py:52} INFO - Started process 2313 to run task
[2023-05-28 00:15:22,177] {standard_task_runner.py:76} INFO - Running: ['***', 'tasks', 'run', 'stock_market_pipeline_fe', 'download_dataset', '2023-05-28T00:04:05.743782+00:00', '--job-id', '10', '--pool', 'default_pool', '--raw', '--subdir', 'DAGS_FOLDER/stock_market_pipeline_fe.py', '--cfg-path', '/tmp/tmp0qvvf22v', '--error-file', '/tmp/tmpmeulx6ou']
[2023-05-28 00:15:22,178] {standard_task_runner.py:77} INFO - Job 10: Subtask download_dataset
[2023-05-28 00:15:22,202] {logging_mixin.py:104} INFO - Running <TaskInstance: stock_market_pipeline_fe.download_dataset 2023-05-28T00:04:05.743782+00:00 [running]> on host a783e9c6e3ac
[2023-05-28 00:15:22,230] {taskinstance.py:1302} INFO - Exporting the following env vars:
AIRFLOW_CTX_DAG_OWNER=***_fe
AIRFLOW_CTX_DAG_ID=stock_market_pipeline_fe
AIRFLOW_CTX_TASK_ID=download_dataset
AIRFLOW_CTX_EXECUTION_DATE=2023-05-28T00:04:05.743782+00:00
AIRFLOW_CTX_DAG_RUN_ID=manual__2023-05-28T00:04:05.743782+00:00
[2023-05-28 00:20:24,441] {taskinstance.py:1501} ERROR - Task failed with exception
Traceback (most recent call last):
  File "/home/airflow/.local/lib/python3.6/site-packages/airflow/models/taskinstance.py", line 1157, in _run_raw_task
    self._prepare_and_execute_task_with_callbacks(context, task)
  File "/home/airflow/.local/lib/python3.6/site-packages/airflow/models/taskinstance.py", line 1331, in _prepare_and_execute_task_with_callbacks
    result = self._execute_task(context, task_copy)
  File "/home/airflow/.local/lib/python3.6/site-packages/airflow/models/taskinstance.py", line 1361, in _execute_task
    result = task_copy.execute(context=context)
  File "/home/airflow/.local/lib/python3.6/site-packages/airflow/operators/python.py", line 150, in execute
    return_value = self.execute_callable()
  File "/home/airflow/.local/lib/python3.6/site-packages/airflow/operators/python.py", line 161, in execute_callable
    return self.python_callable(*self.op_args, **self.op_kwargs)
  File "/opt/airflow/dags/stock_market_pipeline_fe.py", line 25, in download_dataset
    api.dataset_download_files('jacksoncrow/stock-market-dataset', path='/tmp', unzip=True)
  File "/home/airflow/.local/lib/python3.6/site-packages/kaggle/api/kaggle_api_extended.py", line 1245, in dataset_download_files
    with zipfile.ZipFile(outfile) as z:
  File "/usr/local/lib/python3.6/zipfile.py", line 1113, in __init__
    self.fp = io.open(file, filemode)
FileNotFoundError: [Errno 2] No such file or directory: '/tmp/stock-market-dataset.zip'
[2023-05-28 00:20:24,447] {taskinstance.py:1551} INFO - Marking task as UP_FOR_RETRY. dag_id=stock_market_pipeline_fe, task_id=download_dataset, execution_date=20230528T000405, start_date=20230528T001522, end_date=20230528T002024
[2023-05-28 00:20:24,504] {local_task_job.py:149} INFO - Task exited with return code 1
